Workbook

Sheet Your Situation
A1: Health Plan Calculator — Your Situation
B3: Fill in the YELLOW cells below. Everything else calculates automatically.
B5: YOUR PROFILE
B7: Age | C7: 40 | D7: Turns 41 in June 2026 — premiums may adjust slightly at renewal
B8: County | C8: Boulder | D8: Both Longmont and Boulder are in Boulder County (same rating area)
B9: Tobacco use | C9: No | D9: Non-tobacco rates apply
B11: INCOME & SUBSIDIES
B13: Estimated 2026 annual income | C13: 42000 | D13: CHANGE THIS — it's the single most important number in this whole spreadsheet
B14: Federal Poverty Level (single, 2026) | C14: 15650 | D14: Set by the federal government — do not change
B15: Income as % of FPL | C15: =IF(C13="","",ROUND(C13/C14*100,0)) -> 268 | D15: Calculated — determines subsidy tier
B16: CSR Tier | C16: =IF(C15="","",IF(C15<=150,"94% CSR — Silver acts like Platinum!",IF(C15<=200,"87% CSR — Silver acts like Gold+",IF(C15<=250,"73% CSR — moderate improvement on Silver",IF(C15<=400,"No CSR — compare Silver vs Gold carefully","No subsidies at all (over 400% FPL)"))))) -> No CSR — compare Silver vs Gold carefully | D16: CSR only applies to Silver plans bought through Connect for Health CO
B17: Colorado Premium Assistance (CPA) | C17: =IF(C15="","",IF(C15<=400,"$80/mo ($960/yr) — state-funded, never repaid","Not eligible (over 400% FPL)")) -> $80/mo ($960/yr) — state-funded, never repaid | D17: Applied automatically — NOT a tax credit, no clawback risk
B19: ESTIMATED MONTHLY PREMIUMS (age 40, Boulder County, non-tobacco)
B20: Benchmark (SLCSP) premium — estimated | C20: 600 | D20: ~$580-$620 for Boulder County age 40. Replace with exact number from connectforhealthco.com
B21: Expected contribution (% of income) | C21: =IF(C15="","",IF(C15<=133,2.1%,IF(C15<=150,3.14%+(C15-133)/(150-133)*(4.19%-3.14%),IF(C15<=200,4.19%+(C15-150)/(200-150)*(6.6%-4.19%),IF(C15<=250,6.6%+(C15-200)/(250-200)*(8.44%-6.6%),IF(C15<=300,8.44%+(C15-250)/(300-250)*(9.96%-8.44%),IF(C15<=400,9.96%,0))))))) -> 0.089872 | D21: From IRS Rev. Proc. 2025-25 — the 2026 sliding scale (higher than 2021-2025)
B22: Your expected monthly contribution | C22: =IF(C21="","",ROUND(C13*C21/12,0)) -> 315 | D22: What the government expects you to pay toward the benchmark Silver plan
B23: Federal APTC (monthly) | C23: =IF(C15>400,"$0 — over subsidy cliff",IF(C22="","",MAX(0,C20-C22))) -> 285 | D23: Benchmark premium minus your expected contribution. This IS a tax credit — reconciled when you file.
B24: Colorado Premium Assistance (monthly) | C24: =IF(C15>400,0,80) -> 80 | D24: State-funded, NOT a tax credit, never repaid even if income changes
B26: NET MONTHLY PREMIUM (benchmark Silver) | C26: =IF(C15>400,C20,MAX(1,C20-C23-C24)) -> 235 | D26: Minimum is $1/mo (CPA won't reduce below $1). This is what you actually pay each month.
B28: YOUR HEALTHCARE USAGE
B30: PCP visits per year | C30: 4 | D30: How many times you see your primary care doctor
B31: Specialist visits per year | C31: 0 | D31: Visits to any specialist (not PCP)
B32: Urgent care visits per year | C32: 1 | D32: Walk-in urgent care, not ER
B33: Monthly generic Rx scripts | C33: 2 | D33: Number of generic medications per month (Tier 1 = $0 on all plans)
B36: REFERENCE: Income Thresholds (single person, 2026)
B37: FPL % | C37: Annual Income | D37: What Happens
B38: 138% (Medicaid cutoff) | C38: 21597 | D38: Below this → likely still on Medicaid
B39: 150% | C39: 23475 | D39: 94% CSR — best Silver cost-sharing
B40: 200% | C40: 31300 | D40: 87% CSR — very good Silver cost-sharing
B41: 250% | C41: 39125 | D41: 73% CSR — moderate Silver improvement
B42: 300% | C42: 46950 | D42: No CSR — premium credits + CPA only
B43: 400% (SUBSIDY CLIFF) | C43: 62600 | D43: Above this → NO help at all

Sheet Plan Comparison
A1: Plan-by-Plan Comparison — Select Health Colorado 2026
B3: =CONCATENATE("Your income: ",TEXT('Your Situation'!C13,"$#,##0")," (",'Your Situation'!C15,"% FPL) | CSR: ",'Your Situation'!C16," | Net monthly premium (benchmark): ",TEXT('Your Situation'!C26,"$#,##0")) -> Your income: $42,000 (268% FPL) | CSR: No CSR — compare Silver vs Gold carefully | Net monthly premium (benchmark): $235
B5: Plan Feature | C5: Silver $3400 Deductible (The plan you were looking at) | D5: Colorado Option Silver (Public option — $0 PCP) | E5: Gold $1500 Deductible (Higher premium, lower costs)
B6: EST. MONTHLY PREMIUM (after APTC + CPA) | C6: ='Your Situation'!C26 -> 235 | D6: ='Your Situation'!C26 -> 235 | E6: ='Your Situation'!C26+65 -> 300
B7: Note: Silver premiums above are estimates — the two Silver plans may differ by $10-20/mo. Gold is typically ~$50-80/mo more after subsidies. Verify exact numbers at connectforhealthco.com.
B9: COST-SHARING DETAILS (Standard — before any CSR)
B10: Deductible (individual) | C10: $3,400 | D10: $4,400 | E10: $1,500
B11: Max Out-of-Pocket (individual) | C11: $10,600 | D11: $9,800 | E11: $9,000
B12: Coinsurance (after deductible) | C12: 40% | D12: 0.4 | E12: 25%
B13: PCP / Behavioral Health visit | C13: $35 copay | D13: $0 copay | E13: $15 copay
B14: Specialist visit | C14: $80 copay | D14: $90 copay | E14: $50 copay
B15: Urgent care | C15: $60 copay | D15: $80 copay | E15: $40 copay
B16: ER visit | C16: $850 after deductible | D16: 40% after deductible | E16: 25% after deductible
B17: Inpatient hospitalization | C17: 40% after deductible | D17: 40% after deductible | E17: 25% after deductible
B18: Virtual visits | C18: $0 | D18: $0 | E18: $0
B19: Preventive care | C19: $0 | D19: $0 | E19: $0
B20: Rx — Tier 1 (generic) | C20: $0 | D20: $0 | E20: $0
B21: Rx — Tier 2 (preferred generic) | C21: $15 | D21: 20 | E21: $10
B22: Rx deductible | C22: $1,500 | D22: Combined with medical | E22: $600
B24: HOW CSR CHANGES SILVER PLANS (by income)
B25: If your income is... | C25: Silver $3400 | D25: CO Option Silver | E25: Gold $1500
B26: ~$23K (150%) → 94% CSR | C26: Ded: $0 | OOP: $3,200 PCP: $0 | D26: Ded: $100 | OOP: $1,375 PCP: $0 | E26: No CSR on Gold
B27: ~$31K (200%) → 87% CSR | C27: Ded: $100 | OOP: $3,300 PCP: $10 | D27: Ded: $950 | OOP: $3,350 PCP: $0 | E27: No CSR on Gold
B28: ~$39K (250%) → 73% CSR | C28: Ded: $3,000 | OOP: $7,500 PCP: $30 | D28: Ded: $2,850 | OOP: $8,000 PCP: $0 | E28: No CSR on Gold
B29: ~$47K+ (300%+) → No CSR | C29: Standard rates above | D29: Standard rates above | E29: Standard rates above
B31: ESTIMATED TOTAL ANNUAL COST (Premiums + Out-of-Pocket)
B32: =IF('Your Situation'!C15<=150,"Your income qualifies for 94% CSR — costs below reflect near-Platinum benefits",IF('Your Situation'!C15<=200,"Your income qualifies for 87% CSR — costs below reflect enhanced Silver benefits",IF('Your Situation'!C15<=250,"Your income qualifies for 73% CSR — costs below reflect moderate Silver improvement","No CSR at your income — Silver costs are standard (compare carefully with Gold)"))) -> No CSR at your income — Silver costs are standard (compare carefully with Gold)
B34: ROUTINE YEAR (adjusts automatically for your CSR tier)
B35: Cost Component | C35: Silver $3400 | D35: CO Option Silver | E35: Gold $1500
B36: Annual premiums (12 months) | C36: ='Your Situation'!C26*12 -> 2820 | D36: ='Your Situation'!C26*12 -> 2820 | E36: =('Your Situation'!C26+65)*12 -> 3600
B37: PCP visits | C37: ='Your Situation'!C30*IF('Your Situation'!C15<=150,0,IF('Your Situation'!C15<=200,10,IF('Your Situation'!C15<=250,30,35))) -> 140 | D37: ='Your Situation'!C30*0 -> 0 | E37: ='Your Situation'!C30*15 -> 60
B38: Specialist visits | C38: ='Your Situation'!C31*IF('Your Situation'!C15<=150,10,IF('Your Situation'!C15<=200,30,IF('Your Situation'!C15<=250,60,80))) -> 0 | D38: ='Your Situation'!C31*IF('Your Situation'!C15<=150,5,IF('Your Situation'!C15<=200,40,IF('Your Situation'!C15<=250,80,120))) -> 0 | E38: ='Your Situation'!C31*50 -> 0
B39: Urgent care visits | C39: ='Your Situation'!C32*IF('Your Situation'!C15<=150,10,IF('Your Situation'!C15<=200,25,IF('Your Situation'!C15<=250,45,60))) -> 60 | D39: ='Your Situation'!C32*IF('Your Situation'!C15<=150,5,IF('Your Situation'!C15<=200,30,IF('Your Situation'!C15<=250,55,75))) -> 75 | E39: ='Your Situation'!C32*40 -> 40
B40: Prescriptions (Tier 1 generic = $0) | C40: 0 | D40: 0 | E40: 0
B41: ROUTINE YEAR TOTAL | C41: =SUM(C36:C40) -> 3020 | D41: =SUM(D36:D40) -> 2895 | E41: =SUM(E36:E40) -> 3700
B43: WORST CASE: Routine care + 1 ER visit + 3-day hospitalization → you hit Max OOP
B44: In a worst case, you hit your Max Out-of-Pocket — the absolute most you'd pay for care. These amounts adjust for your CSR tier automatically:
C45: Silver $3400 | D45: CO Option Silver | E45: Gold $1500
B46: Max Out-of-Pocket (for your CSR tier) | C46: =IF('Your Situation'!C15<=150,3200,IF('Your Situation'!C15<=200,3300,IF('Your Situation'!C15<=250,7500,10600))) -> 10600 | D46: =IF('Your Situation'!C15<=150,1400,IF('Your Situation'!C15<=200,3350,IF('Your Situation'!C15<=250,8000,9800))) -> 9800 | E46: 9000
B47: + Annual premiums | C47: ='Your Situation'!C26*12 -> 2820 | D47: ='Your Situation'!C26*12 -> 2820 | E47: =('Your Situation'!C26+65)*12 -> 3600
...

Sheet Filing Timing Strategy
A1: Filing Timing Strategy — When to File Your 2025 Tax Return
B3: Filing the 2025 tax return triggers the income data match that causes Medicaid to start a redetermination process. Delaying the filing means more months of free Medicaid coverage. The trade-off: each month on Medicaid is a month of $0 coverage, but each month of delay is less time on the marketplace plan.
B5: TIMING SCENARIOS
B6: When You File | C6: File Early (Feb 2026) | D6: File On Time (Apr 15, 2026) | E6: File on Extension (Oct 15, 2026) | F6: Notes
B7: Approximate Medicaid end date | C7: ~May 2026 | D7: ~Jul 2026 | E7: ~Dec 2026 | F7: Redetermination takes 1-3 months after filing triggers it
B8: Months on FREE Medicaid in 2026 | C8: ~4 | D8: ~6 | E8: ~11 | F8: Each month of Medicaid = $0 premiums AND $0 cost-sharing
B9: Months paying marketplace premiums | C9: ~8 | D9: ~6 | E9: ~1 | F9: Coverage starts 1st of month after SEP enrollment
B10: Your age at enrollment | C10: 40 | D10: 40 (or 41 if after June) | E10: 41 | F10: Minimal premium impact between 40→41 (~2.3% of gross rate)
B11: SEP deadline | C11: ~Jul 2026 | D11: ~Sep 2026 | E11: ~Feb 2027 | F11: 60-90 days from Medicaid end date — DO NOT MISS
B13: DOLLAR IMPACT: How much does timing save?
B14: Monthly premium from tab 1: | C14: ='Your Situation'!C26 -> 235 | F14: This is the net premium after APTC and CPA
C16: File Early (Feb) | D16: File On Time (Apr) | E16: File Extension (Oct)
B17: Months paying premiums | C17: 8 | D17: 6 | E17: 1 | F17: Adjust these — exact months depend on redetermination speed
B18: Total premiums paid in 2026 | C18: ='Your Situation'!C26*C17 -> 1880 | D18: ='Your Situation'!C26*D17 -> 1410 | E18: ='Your Situation'!C26*E17 -> 235 | F18: Premiums ONLY — doesn't include copays/deductibles from care you actually use
B19: + Routine OOP costs (prorated) | C19: =ROUND(('Plan Comparison'!C41-'Plan Comparison'!C36)*C17/12,0) -> 133 | D19: =ROUND(('Plan Comparison'!C41-'Plan Comparison'!C36)*D17/12,0) -> 100 | E19: =ROUND(('Plan Comparison'!C41-'Plan Comparison'!C36)*E17/12,0) -> 17
B20: TOTAL COST IN 2026 | C20: =C18+C19 -> 2013 | D20: =D18+D19 -> 1510 | E20: =E18+E19 -> 252
B21: Savings vs. filing early | C21: (baseline) | D21: =C20-D20 -> 503 | E21: =C20-E20 -> 1761 | F21: This is real money — every month on Medicaid is a month of $0 premiums
B23: IMPORTANT CAVEATS
B24: No gap in coverage | C24: When Medicaid ends, the marketplace plan should start the 1st of the next month. Enroll IMMEDIATELY when you get the termination notice to avoid any gap.
B25: Filing an extension ≠ not filing | C25: Filing for a tax extension gives you until Oct 15 to file the return. However, if you owe any tax, the payment is still due April 15. The extension only extends the filing deadline, not the payment deadline.
B26: Medicaid may redetermine on its own | C26: Colorado periodically runs redeterminations. Even without filing, your Medicaid eligibility could be reviewed based on other data matches. Filing gives more control over timing.
B27: 2026: No APTC repayment cap | C27: Starting in 2026, if you receive more APTC than you're entitled to (because income ends up higher than estimated), you must repay the FULL excess — there's no cap. Estimate income carefully.
B28: SEP window is firm | C28: The Special Enrollment Period is 60-90 days from the date Medicaid ends. If you miss it, you CANNOT enroll until November 2026 open enrollment. Set calendar reminders.
B29: Colorado state return has a checkbox | C29: When filing the Colorado state tax return, there's a checkbox that can connect you to Connect for Health Colorado and trigger an SEP. Use this.

Sheet Decision Guide
A1: Decision Guide — Which Plan Is Best?
B3: IF YOUR INCOME IS... → HERE'S THE BEST PLAN
B4: Income Range | C4: Best Plan | D4: Why | E4: Est. Monthly Premium
B5: Under $22K (below 150% FPL) | C5: Check Medicaid first! | D5: May still be eligible for Health First Colorado | E5: $0 (Medicaid)
B6: $22K–$30K (150–200% FPL) | C6: Silver with 87%/94% CSR | D6: CSR makes Silver act like Platinum. Deductible drops to $0–$100. $0 PCP visits. Hard to beat. | E6: ~$1–$50/mo
B7: $30K–$38K (200–250% FPL) | C7: Silver with 73% CSR (the plan you were looking at) | D7: Still gets CSR. CO Option Silver also strong here for $0 PCP visits. | E7: ~$50–$150/mo
B8: $38K–$60K (250–400% FPL) | C8: Compare Silver vs Gold | D8: No CSR. Silver's 40% coinsurance is steep. Gold's $1,500 deductible + 25% coinsurance may save money if she uses care. | E8: ~$150–$400/mo
B9: Over $60K (400%+ FPL) | C9: Gold if she uses care Bronze if healthy | D9: No subsidies. Full price. Gold gives predictability if she expects to use care. | E9: ~$500–$700/mo (full price)
B11: ACTION ITEMS — IN ORDER OF PRIORITY
B12: 1. Pin down 2026 income | C12: This single number determines CSR tier, premium subsidy, and CPA eligibility. A few thousand dollars can change everything. | E12: HIGH
B13: 2. Decide when to file 2025 taxes | C13: See the Filing Timing Strategy tab. April 15 is the sweet spot — balances Medicaid months with enrollment timing. | E13: HIGH
B14: 3. Verify Rx on formulary | C14: selecthealth.org/pharmacy — confirm all medications are Tier 1 (generic). If any are Tier 2+, factor in cost difference. | E14: MEDIUM
B15: 4. Confirm PCP in-network | C15: DONE — your doctor is confirmed in the Select Health network. | E15: DONE
B16: 5. Enroll through Connect for Health CO | C16: MUST use the marketplace — NOT directly with Select Health — to get any subsidies, CSR, or CPA. | E16: HIGH
B17: 6. Compare exact premiums online | C17: Use connectforhealthco.com Estimate & Explore tool with your zip code, age 40, and income for exact premium quotes. | E17: MEDIUM
B18: 7. Set SEP deadline reminders | C18: The moment Medicaid termination notice arrives, set a 30-day and 60-day calendar reminder. Missing SEP = no coverage until Nov. | E18: HIGH
